<?xml version="1.0"?>
<robot name="drivebot" xmlns:xacro="http://www.ros.org/wiki/xacro">

  <xacro:include filename="$(find drivebot_description)/urdf/materials.xacro" />
  <xacro:include filename="$(find drivebot_description)/urdf/macros.xacro" />

  <!-- X = front/back, Y = right/left, Z = up/down  -->
  <xacro:property name="bodyX" value="0.9" />
  <xacro:property name="bodyY" value="0.7" />
  <xacro:property name="bodyZ" value="0.2" />
  <xacro:property name="bodyMass" value="5" />

  <xacro:property name="wheelR" value="${0.1}" />
  <xacro:property name="wheelH" value="0.05" />
  <xacro:property name="wheelMass" value="1" />

  <xacro:property name="casterR" value="${(wheelR - bodyZ / 2) / 2}" />
  <xacro:property name="casterMass" value="${1}" />

  <link name="base_link" />

  <xacro:boxLink name="body" mass="${bodyMass}" x="${bodyX}" y="${bodyY}" z="${bodyZ}" color="orange" />
  <joint name="base_joint" type="fixed">
    <parent link="base_link" />
    <child link="body_link" />
    <origin xyz="0 0 0" rpy="0 0 0" />
  </joint>
  <gazebo reference="body_link">
    <material>Gazebo/Orange</material>
  </gazebo>

  <xacro:cylinderLink
      name="leftRearWheel" mass="${wheelMass}" radius="${wheelR}" height="${wheelH}" color="red" p ="${pi/2}" />
  <joint name="leftRearWheel_joint" type="continuous">
    <parent link="body_link" />
    <child link="leftRearWheel_link" />
    <origin xyz="${-bodyX/4} ${bodyY/2 + wheelH/2} ${-bodyZ/2}" rpy="0 0 ${pi/2}" />
  </joint>
  <xacro:jointTransmission name="leftRearWheel" />
  <gazebo reference="leftRearWheel_link">
    <material>Gazebo/Red</material>
    <mu1 value="1.0"/>
    <mu2 value="1.0"/>
    <kp value="10000000.0" />
    <kd value="1.0" />
  </gazebo>

  <xacro:cylinderLink
      name="rightRearWheel" mass="${wheelMass}" radius="${wheelR}" height="${wheelH}" color="green" p ="${pi/2}"/>
  <joint name="rightRearWheel_joint" type="continuous">
    <parent link="body_link" />
    <child link="rightRearWheel_link" />
    <origin xyz="${-bodyX/4} ${-bodyY/2 - wheelH/2} ${-bodyZ/2}" rpy="0 0 ${pi/2}" />
  </joint>
  <xacro:jointTransmission name="rightRearWheel" />
  <gazebo reference="rightRearWheel_link">
    <material>Gazebo/Green</material>
    <mu1 value="1.0"/>
    <mu2 value="1.0"/>
    <kp value="10000000.0" />
    <kd value="1.0" />
  </gazebo>

  <xacro:cylinderLink
      name="leftFrontWheel" mass="${wheelMass}" radius="${wheelR}" height="${wheelH}" color="red" p ="${pi/2}" />
  <joint name="leftFrontWheel_joint" type="continuous">
    <parent link="body_link" />
    <child link="leftFrontWheel_link" />
    <origin xyz="${bodyX/4} ${bodyY/2 + wheelH/2} ${-bodyZ/2}" rpy="0 0 ${pi/2}" />
  </joint>
  <xacro:jointTransmission name="leftFrontWheel" />
  <gazebo reference="leftFrontWheel_link">
    <material>Gazebo/Red</material>
    <mu1 value="1.0"/>
    <mu2 value="1.0"/>
    <kp value="10000000.0" />
    <kd value="1.0" />
  </gazebo>

  <xacro:cylinderLink
      name="rightFrontWheel" mass="${wheelMass}" radius="${wheelR}" height="${wheelH}" color="green" p ="${pi/2}"/>
  <joint name="rightFrontWheel_joint" type="continuous">
    <parent link="body_link" />
    <child link="rightFrontWheel_link" />
    <origin xyz="${bodyX/4} ${-bodyY/2 - wheelH/2} ${-bodyZ/2}" rpy="0 0 ${pi/2}" />
  </joint>
  <xacro:jointTransmission name="rightFrontWheel" />
  <gazebo reference="rightFrontWheel_link">
    <material>Gazebo/Green</material>
    <mu1 value="1.0"/>
    <mu2 value="1.0"/>
    <kp value="10000000.0" />
    <kd value="1.0" />
  </gazebo>

  <gazebo>
    <plugin name="imu_plugin" filename="libgazebo_ros_imu.so">
      <alwaysOn>true</alwaysOn>
      <updateRate>100.0</updateRate>
      <bodyName>base_link</bodyName>
      <topicName>imu</topicName>
      <serviceName>imu_service</serviceName>
      <gaussianNoise>0.0001</gaussianNoise>
    </plugin>

    <plugin name="gps_plugin" filename="libhector_gazebo_ros_gps.so">
      <alwaysOn>true</alwaysOn>
      <updateRate>1.0</updateRate>
      <bodyName>base_link</bodyName>
      <topicName>fix</topicName>
      <frameId>base_link</frameId>
      <gaussianNoise>0.775</gaussianNoise>
    </plugin>

    <plugin name="base_link_p3d_plugin" filename="libgazebo_ros_p3d.so">
      <alwaysOn>true</alwaysOn>
      <updateRate>10.0</updateRate>
      <bodyName>base_link</bodyName>
      <topicName>odometry/ground_truth/map</topicName>
      <frameName>map</frameName>
      <gaussianNoise>0.0</gaussianNoise>
    </plugin>
  </gazebo>

  <!-- ros_control plugin -->
  <gazebo>
    <plugin name="gazebo_ros_control" filename="libgazebo_ros_control.so">
      <robotNamespace>/drivebot</robotNamespace>
      <robotSimType>gazebo_ros_control/DefaultRobotHWSim</robotSimType>
    </plugin>
  </gazebo>

</robot>